
# 자바(Java) 예외 처리 (Exception Handling) 정리

프로그램이 실행 중에 예기치 않은 문제로 인해 정상적인 흐름을 이어갈 수 없는 상황을 **예외(Exception)** 또는 **오류(Error)**라고 합니다. 자바의 예외 처리는 이러한 상황에 미리 대비하여 프로그램이 비정상적으로 종료되는 것을 막고, 안정적으로 계속 실행되도록 관리하는 메커니즘입니다.

## 1. 예외 처리의 기본: `try-catch`

`try-catch` 구문은 예외 처리의 가장 기본이 되는 구조입니다.

- **`try` 블록**: 예외 발생 가능성이 있는 코드를 감싸는 영역입니다.
- **`catch` 블록**: `try` 블록에서 특정 예외가 발생했을 때 실행될 코드를 정의하는 영역입니다.

### 개념 정리
1.  **실행 흐름**: `try` 블록의 코드가 실행되다가 예외가 발생하면, 그 즉시 실행을 멈추고 해당 예외를 처리할 수 있는 `catch` 블록으로 이동합니다.
2.  **예외가 발생하지 않을 경우**: `try` 블록의 코드가 모두 정상적으로 실행되면, `catch` 블록은 건너뛰고 다음 코드로 실행 흐름이 이어집니다.
3.  **다중 `catch` 블록**: 하나의 `try` 블록에 여러 종류의 예외를 처리하기 위해 여러 개의 `catch` 블록을 작성할 수 있습니다. 이때, 구체적인 예외부터 순서대로 작성해야 합니다.
4.  **`Exception` 클래스**: 모든 예외 클래스의 최상위 부모이므로, `catch (Exception e)`는 어떠한 종류의 예외라도 모두 잡아낼 수 있습니다. 보통 가장 마지막에 위치시켜 예상치 못한 모든 예외를 처리하는 용도로 사용됩니다.

### 코드 분석

#### 1) `TryExample1.java` (기본 예외 처리)
0으로 나누는 연산을 시도할 때 발생할 수 있는 `ArithmeticException`을 대비하는 코드입니다.

```java
package chap2_1.exception;

public class TryExample1 {

    public static void main(String[] args) {

        // 예외처리 : 에러를 복구해주는 개념 X , 보험처럼 대비하는 것.
        // 에러가 날 것 같은 곳에다가 예외처리를 적용

        try {
            // 예외 가능성이 있는 코드를 적고
            // 예외가 발생하면 기존 실행흐름을 끊고 바로 catch로 이동
            int n1 = 10, n2 = 2; // n2를 0으로 바꾸면 예외 발생
            System.out.println("나눗셈 시작 !");

            int result = n1 / n2;
            System.out.printf("%d / %d = %d\n", n1, n2, result);
        }catch (Exception e){
            // 에러가 나면 어떻게 할건지를 적습니다.
            System.out.println("0으로 나눌 수 없습니다.");
        }

        System.out.println("프로그램 정상 종료!");
    }
}
```

#### 2) `TryExample2.java` (다중 `catch` 블록)
사용자 입력값에 따라 다양한 종류의 예외가 발생할 수 있는 상황을 처리합니다.
- `NumberFormatException`: 숫자가 아닌 문자열을 `Integer.parseInt()`로 변환하려 할 때 발생합니다.
- `ArithmeticException`: 정수를 0으로 나누려 할 때 발생합니다.
- `NullPointerException`: `null` 값을 가진 참조 변수의 멤버에 접근하려 할 때 발생합니다. (`str.toUpperCase()`)
- `Exception`: 위에서 잡지 못한 그 외의 모든 예외를 처리합니다.

```java
package chap2_1.exception;

import java.util.Scanner;

public class TryExample2 {
    public static void main(String[] args) {

        Scanner sc = new Scanner(System.in);

        while (true) {
            try {
                System.out.print("정수1: ");
                String str1 = sc.nextLine(); // 정수를 문자열로 입력
                int n1 = Integer.parseInt(str1); // 문자열을 정수로 변환

                System.out.print("정수2: ");
                String str2 = sc.nextLine(); // 정수를 문자열로 입력
                int n2 = Integer.parseInt(str2); // 문자열을 정수로 변환

                System.out.println("n1 / n2 = " + (n1 / n2));

                String str = null;
                str.toUpperCase(); // 일부로 오류 발생 시키기 -> NullPointerException 발생

                break;
            // catch는 여러개 입력 가능
            } catch (NumberFormatException e) { // NumberFormatException 문자 오류 시
                // System.out.println(e.getMessage()); // 디버깅용 - 간단한 오류메세지 확인
                // e.printStackTrace(); // 예외처리 안했을 때 뜨던 빨간메세지를 보여줌
                System.out.println("정수로만 입력하세요!");

            } catch (ArithmeticException e) { // ArithmeticException 계산 오류 시
                System.out.println("0으로 나눌 수 없습니다.");

            } catch (Exception e){ // Exception은 에러를 다 받아줌
                // 그래서 마지막에 내가 모르는 오류가 발생할 때 막을 수 있음
                // str.toUpperCase()에서 발생한 NullPointerException이 여기서 잡힘.
                System.out.println("알 수 없는 에러 발생! 조치 후 점검하겠습니다.");
            }
        }
        System.out.println("프로그램 정상 종료!");
    }
}
```

## 2. `finally` 블록

`finally` 블록은 `try-catch` 구문의 마지막에 추가할 수 있는 선택적인 블록으로, **예외 발생 여부와 관계없이 항상 실행되는 코드**를 작성하는 곳입니다.

### 개념 정리
- **항상 실행 보장**: `try` 블록이 정상적으로 끝나든, `catch` 블록으로 이동하든 상관없이 `finally` 블록은 반드시 실행됩니다.
- **자원 해제**: 주로 사용했던 자원(파일 스트림, 데이터베이스 연결, 네트워크 소켓 등)을 안전하게 해제(닫아주기)하는 용도로 사용됩니다.

#### 코드 분석 (`FinallyExample.java`)

```java
package chap2_1.exception;

public class FinallyExample {

    public static void main(String[] args) {
        String[] pets = {"멍멍이", "야옹이", "비둘긔"};

        for (int i = 0; i < 4; i++) {
            try {
                System.out.println(pets[i] + " 키울래요~~");
            } catch (ArrayIndexOutOfBoundsException e) {
                // i가 3일 때, 예외 발생 후 이 블록 실행
                System.out.println("그런 애완동물은 없어요~");
            } finally {
                // 메모리 정리, 네트워크 연결 종료
                // 예외가 나도 실행, 안나도 실행
                // i가 0, 1, 2일 때도 실행되고, i가 3일 때 catch 블록 실행 후에도 실행됨
                System.out.println("애완동물 화이팅\n===========");
            }
        }
    }
    
    // 이 메서드는 try, catch, finally에 모두 return이 있는 특이한 케이스
    // 이 경우, finally 블록의 return 값이 최종적으로 반환됨
    static int foo() { // 정처기 문제
        try {
            return 100;
        } catch (Exception e) {
            return 200;
        } finally {
            return 300;
        }
    }
}
```
- `foo()` 메서드는 `finally`의 강력한 특성을 보여줍니다. `try` 블록에서 `return 100;`을 만나더라도, 메서드를 탈출하기 전에 `finally` 블록이 반드시 실행되므로 최종 반환 값은 `300`이 됩니다.

## 3. 예외 전가(`throws`)와 강제 발생(`throw`)

직접 예외를 처리하지 않고, 자신을 호출한 쪽으로 예외 처리의 책임을 떠넘기거나, 특정 조건에서 의도적으로 예외를 발생시킬 수 있습니다.

### 개념 정리
- **`throws` (예외 전가)**: 메서드 선언부 끝에 작성하며, 이 메서드 내에서 특정 예외가 발생할 수 있음을 명시합니다. 이 메서드를 호출하는 쪽에서는 반드시 `try-catch`로 예외를 처리하거나, 또다시 `throws`로 책임을 넘겨야 합니다.
- **`throw` (예외 강제 발생)**: 코드 블록 내에서 `throw new 예외객체();` 형태로 사용하여, 특정 조건일 때 예외를 고의로 발생시킵니다.
- **사용자 정의 예외**: `Exception` 클래스(또는 그 자식 클래스)를 상속받아 직접 새로운 예외 클래스를 만들 수 있습니다. 이를 통해 비즈니스 로직에 맞는 구체적인 예외를 표현할 수 있습니다. (예: `LoginInvalidException`)

#### 코드 분석

##### 1) `LoginInvalidException.java` (사용자 정의 예외)
로그인 로직에 특화된 예외를 만들기 위해 `Exception`을 상속받아 새로운 예외 클래스를 정의했습니다.

```java
package chap2_1.exception;

public class LoginInvalidException extends Exception{
    public LoginInvalidException(String message) {
        super(message); // 부모 생성자(Exception)에게 에러 메시지를 전달
    }
}
```

##### 2) `LoginUser.java` (`throw`와 `throws` 사용)
`authenticate` 메서드는 로그인 검증 로직을 수행합니다. 계정이나 비밀번호가 일치하지 않는 '예외적인' 상황이 발생하면, `throw`를 사용해 직접 정의한 `LoginInvalidException`을 강제로 발생시킵니다. 그리고 이 메서드가 위험하다는 것을 알리기 위해 메서드 시그니처에 `throws LoginInvalidException`을 명시하여 책임을 호출자에게 넘깁니다.

```java
package chap2_1.exception;

// 로그인 검증을 수행하는 클래스
public class LoginUser {

    private String account; // 가입시 등록한 계정명
    private String password; // 가입시 등록한 비밀번호

    public LoginUser(String account, String password) {
        this.account = account;
        this.password = password;
    }

    // 로그인 검증 기능
    public String authenticate(String inputAccount, String inputPassword)
            throws LoginInvalidException{ // 이 메서드는 에러 가능성이 있는 위험한 메서드이다.
                              // 따라서 사용자는 직접 예외처리를 할 것 !

         /*
            예외를 던지다 : 예외가 발생하면 코드의 흐름이 끊김.
            마치 리턴문 탈출처럼 에러를 활용할 수 있다.
            다만 에러가 발생하면 프로그램이 튕기기 때문에 그에 따른
            예외처리는 호출하는 쪽에게 떠넘긴다.
         */

        // 계정 검증
        if (!this.account.equals(inputAccount)) {
            // 사용자에게 등록되지 않은 계정임을 알림
            // throw(raise): 유발시키다.
            throw new LoginInvalidException("회원가입되지 않은 계정입니다.");
        }

        // 패스워드 검증
        if (!this.password.equals(inputPassword)) {
            // 사용자에게 틀린 비밀번호임을 알림
            throw new LoginInvalidException("비밀번호가 틀렸습니다.");
        }

        System.out.println("로그인에 성공했습니다.");
        return "로그인 성공";
    }
}
```

##### 3) `Main.java` (예외 처리 책임 수행)
`LoginUser`의 `authenticate` 메서드는 `throws`를 통해 예외 처리 책임을 넘겼으므로, 이 메서드를 호출하는 `Main`에서는 반드시 `try-catch`로 예외를 처리해야 합니다.

```java
package chap2_1.exception;

public class Main {
    public static void main(String[] args) {

        // 회원 생성
        LoginUser user = new LoginUser("abc123","1234");

        // 로그인 검증
        // authenticate 메서드가 throws LoginInvalidException을 했으므로,
        // 호출하는 쪽에서 try-catch로 처리해야 함.
        try {
            user.authenticate("abc123","12345"); // 비밀번호 틀리게 입력
        } catch (LoginInvalidException e){
            // e.printStackTrace();
            // LoginUser에서 던진 예외 메시지를 받아서 출력
            System.out.println(e.getMessage());
        }
    }
}
```
